[toc]

## 异常类

Java异常的分类和类结构图:

![](https://raw.githubusercontent.com/binbinbin5/myPics/master/imgs/jabayichang.png)

我们根据Javac对异常的处理要求，将异常类分为2类。

- Exception 是程序正常运行中，可以预料的意外情况，可能并且应该被捕获，进行相应处理。Exception，可以捕获的异常，且作出处理。++也就是要么捕获异常并作出处理，要么继续抛出异常。++

- Error 是指在正常情况下，不大可能出现的情况，绝大部分的 Error 都会导致程序（比如 JVM自身）处于非正常的、不可恢复状态。既然是非正常情况，所以不便于也不需要捕获，常见的比如OutOfMemoryError 之类，都是 Error 的子类。++Error:系统错误，虚拟机出错，我们处理不了，也不需要我们来处理++。

>RuntimeException，经常性出现的错误，可以 捕获，并作出处理，可以不捕获，也可以不用抛出。ArrayIndexOutOfBoundsException像这种异常可以不捕获，为什么呢？在一个程序里，使用很多数组，如果使用一次捕获一次，则很累。 

Exception 又分为可检查（checked）异常和不检查（unchecked）异常：
![](https://raw.githubusercontent.com/binbinbin5/myPics/master/imgs/java%E5%BC%82%E5%B8%B8.png)


### 常见异常
- 非检查异常（unckecked exception）：

    ++RuntimeException 以及他们的子类。javac在编译时，不会提示和发现这样的异常，不要求在程序中处理这些异常++。所以如果愿意，我们可以编写代码处理（使用try...catch...finally）这样的异常，也可以不处理。对于这些异常，我们应该修正代码，而不是去通过异常处理器处理 。这样的异常发生的原因多半是代码写的有问题。如：
  
```
除0错误ArithmeticException，
错误的强制类型转换错误ClassCastException，
数组索引越界ArrayIndexOutOfBoundsException，
使用了空对象NullPointerException，
算术异常：ArithmeticException
java.lang.NumberFormatException 字符串转换为数字异常；出现原因：字符型数据中包含非数字型字符；
java.lang.IndexOutOfBoundsException 数组角标越界异常，常见于操作数组对象时发生；
java.lang.ClassCastException 数据类型转换异常；
java.lang.NoClassDefFoundException 未找到类定义错误；
java.lang.NoSuchMethodException 方法不存在异常；
java.lang.IllegalArgumentException 方法传递参数错误。
```

    
- ==检查异常（checked exception）==
    
    ++强制要求程序员为这样的异常做预备处理工作（使用try...catch...finally或者throws）++。在方法中要么用try-catch语句捕获它并处理，要么用throws子句声明抛出它，否则编译不会通过。这样的异常一般是由程序的运行环境导致的。因为程序可能被运行在各种未知的环境下，而程序员无法干预用户如何使用他编写的程序，于是程序员就应该为这样的异常时刻准备着。如


```
SQLException , 数据库
IOException, 输入输出异常
ClassNotFoundException ， 类没有发现异常
InterruptedException, 中断异常

```



### 处理异常注意点
1. 不要推诿或延迟处理异常，就地解决最好，并且需要实实在在的进行处理，而不是只捕捉，不动作。 
2. 一个函数尽管抛出了多个异常，但是只有一个异常可被传播到调用端。最后被抛出的异常时唯一被调用端接收的异常，其他异常都会被吞没掩盖。如果调用端要知道造成失败的最初原因，程序之中就绝不能掩盖任何异常。 还有当一个try后跟了很多个catch时，必须先捕获小的异常再捕获大的异常
3. 不要在finally代码块中处理返回值。 当遇到return语句的时候，执行函数会立刻返回。但是，在Java语言中，如果存在finally就会有例外。除了return语句，try代码块中的break或continue语句也可能使控制权进入finally代码块。 请勿在try代码块中调用return、break或continue语句。万一无法避免，一定要确保finally的存在不会改变函数的返回值。 函数返回值有两种类型：值类型与对象引用。对于对象引用，要特别小心，如果在finally代码块中对函数返回的对象成员属性进行了修改，即使不在finally块中显式调用return语句，这个修改也会作用于返回值上。 
4. 勿将异常用于控制流。 
5. 如无必要，勿用异常。 
6. 上传下载不能抛异常。上传下载一定要关流。 
7. 异常不是错误。异常控制代码流程不利于代码简单易读。 
8. 继承某个异常时，重写方法时，要么不抛出异常，要么抛出一模一样的异常
9. 异常要捕获特定异常，而不是通用异常,异常先小再大，不过注意try..catch有开销，影响代码优化
10. 不要生吞异常，就是可能不会发生的异常也要加上try..catch

先来看下面这段代码，有没有发现一些问题？


```
try {
  // ...
  int i = Integer.parseInt(null);
} catch (Exception e) {
}
```

以上的这段代码，看似“正常”，却违背了异常处理的两个基本原则：

1. 第一，尽量不要捕获通用异常，也就是像 Exception 这样的异常，而是应该捕获特定异常，这样更有助于你发现问题；
1. 第二，不要忽略异常，像上面的这段代码只是加了 catch，但没有进行如何的错误处理，信息就已经输出了，这样在程序出现问题的时候，根本找不到问题出现的原因，因此要切记不要直接忽略异常。
## 初识异常


```
package com.example;
import java. util .Scanner ;
public class AllDemo
{
      public static void main (String [] args )
      {
            System . out. println( "----欢迎使用命令行除法计算器----" ) ;
            CMDCalculate ();
      }
      public static void CMDCalculate ()
      {
            Scanner scan = new Scanner ( System. in );
            int num1 = scan .nextInt () ;
            int num2 = scan .nextInt () ;
            int result = devide (num1 , num2 ) ;
            System . out. println( "result:" + result) ;
            scan .close () ;
      }
      public static int devide (int num1, int num2 ){
            return num1 / num2 ;
      }
}
// 前者由于整数除0引发，后者是输入的数据不能被转换为int类型引发。
```

```
----欢迎使用命令行除法计算器----
0
Exception in thread "main" java.lang.ArithmeticException : / by zero
     at com.example.AllDemo.devide( AllDemo.java:30 )
     at com.example.AllDemo.CMDCalculate( AllDemo.java:22 )
     at com.example.AllDemo.main( AllDemo.java:12 )
```

```
----欢迎使用命令行除法计算器----
r
Exception in thread "main" java.util.InputMismatchException
     at java.util.Scanner.throwFor( Scanner.java:864 )
     at java.util.Scanner.next( Scanner.java:1485 )
     at java.util.Scanner.nextInt( Scanner.java:2117 )
     at java.util.Scanner.nextInt( Scanner.java:2076 )
     at com.example.AllDemo.CMDCalculate( AllDemo.java:20 )
     at com.example.AllDemo.main( AllDemo.java:12 )
```
异常是在执行某个函数时引发的，而函数又是层级调用，形成调用栈的，因为，只要一个函数发生了异常，那么他的所有的caller都会被异常影响。当这些被影响的函数以异常信息输出时，就形成的了异常追踪栈。异常最先发生的地方，++叫做异常抛出点。++
![](https://raw.githubusercontent.com/binbinbin5/myPics/master/imgs/yichangpaochudian.png)

从上面的例子可以看出，当devide函数发生除0异常时，devide函数将抛出ArithmeticException异常，因此调用他的CMDCalculate函数也无法正常完成，因此也发送异常，而CMDCalculate的caller——main 因为CMDCalculate抛出异常，也发生了异常，这样一直向调用栈的栈底回溯。这种行为叫做异常的冒泡，异常的冒泡是为了在当前发生异常的函数或者这个函数的caller中找到最近的异常处理程序。由于这个例子中没有使用任何异常处理机制，因此异常最终由main函数抛给JRE，导致程序终止。

上面的代码不使用异常处理机制，也可以顺利编译，因为2个异常都是非检查异常。但是下面的例子就必须使用异常处理机制，因为异常是检查异常。

代码中选择使用throws声明异常，让函数的调用者去处理可能发生的异常。但是为什么只throws了IOException呢？因为FileNotFoundException是IOException的子类，在处理范围内。


```
public void testException() throws IOException
{
    //FileInputStream的构造函数会抛出FileNotFoundException，因为FileNotFoundException是IOException的子类，所以不用再抛出FileNotFoundException
    FileInputStream fileIn = new FileInputStream("E:\\a.txt");
    
    int word;
    //read方法会抛出IOException
    while((word =  fileIn.read())!=-1) 
    {
        System.out.print((char)word);
    }
    //close方法会抛出IOException
    fileIn.close();
}
```

## 异常处理的基本语法
- 在编写代码处理异常时，对于检查异常，有2种不同的处理方式：使用try...catch...finally语句块处理它。

- 或者，在函数签名中使用throws 声明交给函数调用者caller去解决。

### try...catch...finally 语句块。

```
try{
     //try块中放可能发生异常的代码。
     //如果执行完try且不发生异常，则接着去执行finally块和finally后面的代码（如果有的话）。
     //如果发生异常，则尝试去匹配catch块。

}catch(SQLException SQLexception){
     //每一个catch块用于捕获并处理一个特定的异常，或者这异常类型的子类。Java7中可以将多个异常声明在一个catch中。
     //catch后面的括号定义了异常类型和异常参数。如果异常与之匹配且是最先匹配到的，则虚拟机将使用这个catch块来处理异常。
     //在catch块中可以使用这个块的异常参数来获取异常的相关信息。异常参数是这个catch块中的局部变量，其它块不能访问。
    //如果当前try块中发生的异常在后续的所有catch中都没捕获到，则先去执行finally，然后到这个函数的外部caller中去匹配异常处理器。
    //如果try中没有发生异常，则所有的catch块将被忽略。

}catch(Exception exception){
    //...
}finally{
   //finally块通常是可选的。
   //无论异常是否发生，异常是否匹配被处理，finally都会执行。
   //一个try至少要有一个catch块，否则， 至少要有1个finally块。但是finally不是用来处理异常的，finally不会捕获异常。
   //finally主要做一些清理工作，如流的关闭，数据库连接的关闭等。 
}
```
>需要注意的地方
1. try块中的局部变量和catch块中的局部变量（包括异常变量），以及finally中的局部变量，他们之间不可共享使用。
 
2. 每一个catch块用于处理一个异常。异常匹配是按照catch块的顺序从上往下寻找的，只有第一个匹配的catch会得到执行。匹配时，不仅运行精确匹配，也支持父类匹配，因此，如果同一个try块下的多个catch异常类型有父子关系，应该将子类异常放在前面，父类异常放在后面，这样保证每个catch块都有存在的意义。
 
3. java中，异常处理的任务就是将执行控制流从异常发生的地方转移到能够处理这种异常的地方去。也就是说：当一个函数的某条语句发生异常时，这条语句的后面的语句不会再执行，它失去了焦点。执行流跳转到最近的匹配的异常处理catch代码块去执行，异常被处理完后，执行流会接着在“处理了这个异常的catch代码块”后面接着执行。

- 有的编程语言当异常被处理后，控制流会恢复到异常抛出点接着执行，这种策略叫做：resumption model of exception handling（恢复式异常处理模式 ）
- 而Java则是让执行流恢复到处理了异常的catch块后接着执行，这种策略叫做：termination model of exception handling（终结式异常处理模式）

```
public static void main(String[] args){
        try {
            foo();
        }catch(ArithmeticException ae) {
            System.out.println("处理异常");
        }
}
public static void foo(){
        int a = 5/0;  //异常抛出点
        System.out.println("为什么还不给我涨工资!!!");  //////////////////////不会执行
}
```
>注意：
- try-catch 代码段会产生额外的性能开销，或者换个角度说，它往往会影响 JVM 对代码进行优化，所以建议仅捕获有必要的代码段，尽量不要一个大的 try 包住整段的代码；与此同时，利用异常控制代码流程，也不是一个好主意，远比我们通常意义上的条件语句（if/else、switch）要低效。
- Java 每实例化一个 Exception，都会对当时的栈进行快照，这是一个相对比较重的操作。如果发生的非常频繁，这个开销可就不能被忽略了。

### throws 函数声明
throws声明：如果一个方法内部的代码会抛出检查异常（checked exception），而方法自己又没有完全处理掉，则javac保证你必须在方法的签名上使用throws关键字声明这些可能抛出的异常，否则编译不通过。

throws是另一种处理异常的方式，它不同于try...catch...finally，throws仅仅是将函数中可能出现的异常向调用者声明，而自己则不具体处理。

采取这种异常处理的原因可能是：方法本身不知道如何处理这样的异常，或者说让调用者处理更好，调用者需要为可能发生的异常负责。
```
public void foo() throws ExceptionType1 , ExceptionType2 ,ExceptionTypeN
{ 
     //foo内部可以抛出 ExceptionType1 , ExceptionType2 ,ExceptionTypeN 类的异常，或者他们的子类的异常对象。
}
```
### finally块
finally块不管异常是否发生，只要对应的try执行了，则它一定也执行。==只有一种方法让finally块不执行：System.exit()==。因此finally块通常用来做资源释放操作：关闭文件，关闭数据库连接等等。

```
良好的编程习惯是：在try块中打开资源，在finally块中清理释放这些资源。
```
>需要注意的地方:
1. finally块没有处理异常的能力。处理异常的只能是catch块。
2. 在同一try...catch...finally块中 ，如果try中抛出异常，且有匹配的catch块，则先执行catch块，再执行finally块。如果没有catch块匹配，则先执行finally，然后去外面的调用者中寻找合适的catch块。
3. 在同一try...catch...finally块中 ，try发生异常，且匹配的catch块中处理异常时也抛出异常，那么后面的finally也会执行：首先执行finally块，然后去外围调用者中寻找合适的catch块。

>例子：

```
/**
* try catch
*
* try 里面的return可以返回但不能结束方法.
*
* catch ,finnally ,或者正常的return才可以结束本方法.
* 
* 因为finnally始终要执行,所以当catch和finnally里都有return ,catch里的这个return不结束方法
*/

public static int method_1() {
		int a = 1;
		try {
			return a;
		} catch (Exception e) {
			System.out.println("11");
		} finally {
			++a;
			return a;
		}
		
	}
答案是: 2




干货2:

public static int method_2() {
		int a = 1;
		try {
			int  u=1/0;
			return a;
		} catch (Exception e) {
			System.out.println("11");
		} finally {
			++a;
			return a;
		}
	
	}

答案是 : 11 2

干货3:

public static int method_3() {
		int a = 1; 
		try {
			int  u=1/0;
			return a;
		} catch (  Exception e) {
			System.out.println("11");
			return a;
		} finally {
			++a;
		
		}
	 
	}

答案是 : 11  1


干货4:

public static int method_4() {
		int a = 1;
		try {
			return a;
		} catch (Exception e) {
			System.out.println("11");
		} finally {
			++a;
		}
		return a;
	}

答案是 : 1


干货5:

	public static int method_5() {
		int a = 1;
		try {
			int  u=1/0;
			return a;
		} catch (Exception e) {
			System.out.println("11");
			return a+1;
		} finally {
			++a;
			System.out.println("22");
		}
 
	}

答案是 : 11  22  2

```


### throw 异常抛出语句


```
throw exceptionObject
```

- 程序员也可以通过throw语句手动显式的抛出一个异常。throw语句的后面必须是一个异常对象。
- throw 语句必须写在函数中，执行throw 语句的地方就是一个异常抛出点，它和由JRE自动形成的异常抛出点没有任何差别。
```
public void save(User user)
{
      if(user  == null) 
          throw new IllegalArgumentException("User对象为空");
      //......
        
}
```
### throws和throw


1. throw 语句用在**方法体内**，表示抛出异常由方法体内的语句处理，执行 throw 一定是抛出了某种异常；
1. throws 语句用在**方法声明的后面**，该方法的调用者要对异常进行处理，throws 代表可能会出现某种异常，并不一定会发生这种异常。


```
class MyException extends Exception {
    public MyException() {}
    public MyException(String msg) {
        super(msg);
    }
}

public class Demo3 {

    public static void main(String[] args) {
        try {
            test();
        } catch (MyException e) {
            System.out.println("Catch My Exception");
            e.printStackTrace();
        }
    }
    public static void test() throws MyException{
        try {
            int i = 10/0;
              System.out.println("i="+i); 
        } catch (ArithmeticException e) {
            throw new MyException("This is MyException"); 
        }
    }
}
```

## 异常的链化
在一些大型的，模块化的软件开发中，一旦一个地方发生异常，则如骨牌效应一样，将导致一连串的异常。假设B模块完成自己的逻辑需要调用A模块的方法，如果A模块发生异常，则B也将不能完成而发生异常，但是B在抛出异常时，会将A的异常信息掩盖掉，这将使得异常的根源信息丢失。异常的链化可以将多个模块的异常串联起来，使得异常信息不会丢失。

>异常链化:以一个异常对象为参数构造新的异常对象。新的异对象将包含先前异常的信息。这项技术主要是异常类的一个带Throwable参数的函数来实现的。这个当做参数的异常，我们叫他根源异常（cause）。

查看Throwable类源码，可以发现里面有一个Throwable字段cause，就是它保存了构造时传递的根源异常参数。这种设计和链表的结点类设计如出一辙，因此形成链也是自然的了。
```
public class Throwable implements Serializable {
    private Throwable cause = this;
   
    public Throwable(String message, Throwable cause) {
        fillInStackTrace();
        detailMessage = message;
        this.cause = cause;
    }
     public Throwable(Throwable cause) {
        fillInStackTrace();
        detailMessage = (cause==null ? null : cause.toString());
        this.cause = cause;
    }
    
    //........
}
```
下面是一个例子，演示了异常的链化：从命令行输入2个int，将他们相加，输出。输入的数不是int，则导致getInputNumbers异常，从而导致add函数异常，则可以在add函数中抛出一个链化的异常。
```
public static void main(String[] args)
{   
    System.out.println("请输入2个加数");
    int result;
    try
    {
        result = add();
        System.out.println("结果:"+result);
    } catch (Exception e){
        e.printStackTrace();
    }
}
//获取输入的2个整数返回
private static List<Integer> getInputNumbers()
{
    List<Integer> nums = new ArrayList<>();
    Scanner scan = new Scanner(System.in);
    try {
        int num1 = scan.nextInt();
        int num2 = scan.nextInt();
        nums.add(new Integer(num1));
        nums.add(new Integer(num2));
    }catch(InputMismatchException immExp){
        throw immExp;
    }finally {
        scan.close();
    }
    return nums;
}

//执行加法计算
private static int add() throws Exception
{
    int result;
    try {
        List<Integer> nums =getInputNumbers();
        result = nums.get(0)  + nums.get(1);
    }catch(InputMismatchException immExp){
        throw new Exception("计算失败",immExp);  //链化:以一个异常对象为参数构造新的异常对象。
    }
    return  result;
}
```

```
/*
请输入2个加数
r 1
java.lang.Exception: 计算失败
    at practise.ExceptionTest.add(ExceptionTest.java:53)
    at practise.ExceptionTest.main(ExceptionTest.java:18)
Caused by: java.util.InputMismatchException
    at java.util.Scanner.throwFor(Scanner.java:864)
    at java.util.Scanner.next(Scanner.java:1485)
    at java.util.Scanner.nextInt(Scanner.java:2117)
    at java.util.Scanner.nextInt(Scanner.java:2076)
    at practise.ExceptionTest.getInputNumbers(ExceptionTest.java:30)
    at practise.ExceptionTest.add(ExceptionTest.java:48)
    ... 1 more

*/
```
![](https://raw.githubusercontent.com/binbinbin5/myPics/master/imgs/qewgqergqd.png)

## 自定义异常

如果要自定义异常类，则扩展Exception类即可，因此这样的自定义异常都属于检查异常（checked exception）。如果要自定义非检查异常，则扩展自RuntimeException。

按照国际惯例，自定义的异常应该总是包含如下的构造函数：
- 一个无参构造函数
- 一个带有String参数的构造函数，并传递给父类的构造函数。
- 一个带有String参数和Throwable参数，并都传递给父类构造函数
- 一个带有Throwable 参数的构造函数，并传递给父类的构造函数。

下面是IOException类的完整源代码，可以借鉴。
```
public class IOException extends Exception
{
    static final long serialVersionUID = 7818375828146090155L;

    public IOException()
    {
        super();
    }

    public IOException(String message)
    {
        super(message);
    }

    public IOException(String message, Throwable cause)
    {
        super(message, cause);
    }

    
    public IOException(Throwable cause)
    {
        super(cause);
    }
}

```
## 异常的注意事项
当子类重写父类的带有 throws声明的函数时，其throws声明的异常必须在父类异常的可控范围内——用于处理父类的throws方法的异常处理器，必须也适用于子类的这个带throws方法 。这是为了支持多态。
>例如，父类方法throws 的是2个异常，子类就不能throws 3个及以上的异常。父类throws IOException，子类就必须throws IOException或者IOException的子类。
 至于为什么？我想，也许下面的例子可以说明。
```
class Father
{
    public void start() throws IOException
    {
        throw new IOException();
    }
}

class Son extends Father
{
    public void start() throws Exception
    {
        throw new SQLException();
    }
}
/**********************假设上面的代码是允许的（实质是错误的）***********************/
class Test
{
    public static void main(String[] args)
    {
        Father[] objs = new Father[2];
        objs[0] = new Father();
        objs[1] = new Son();

        for(Father obj:objs)
        {
        //因为Son类抛出的实质是SQLException，而IOException无法处理它。
        //那么这里的try。。catch就不能处理Son中的异常。
        //多态就不能实现了。
            try {
                 obj.start();
            }catch(IOException)
            {
                 //处理IOException
            }
         }
   }
}
```
Java程序可以是多线程的。每一个线程都是一个独立的执行流，独立的函数调用栈。如果程序只有一个线程，那么没有被任何代码处理的异常 会导致程序终止。如果是多线程的，那么没有被任何代码处理的异常仅仅会导致异常所在的线程结束。
也就是说，Java中的异常是线程独立的，线程的问题应该由线程自己来解决，而不要委托到外部，也不会直接影响到其它线程的执行。

## finally块和return

首先一个不容易理解的事实：++在 try块中即便有return，break，continue等改变执行流的语句，finally也会执行。++
```
public static void main(String[] args)
{
    int re = bar();
    System.out.println(re);
}
private static int bar() 
{
    try{
        return 5;
    } finally{
        System.out.println("finally");
    }
}
/*输出：
finally
*/

```
也就是说：try...catch...finally中的return 只要能执行，就都执行了，他们共同向同一个内存地址（假设地址是0x80）写入返回值，后执行的将覆盖先执行的数据，而真正被调用者取的返回值就是最后一次写入的。

++**finally中的return 会覆盖 try 或者catch中的返回值。**++

1. 不管try,finally都会执行；
2. 在try中return，在finally执行前会把结果保存起来，即使在finally中有修改也以try中保存的值为准，但如果是引用类型，修改的属性会以finally修改后的为准；
3. 如果try/finally都有return，直接返回finally中的return。

>因此建议：
- 不要在fianlly中使用return。
- 不要在finally中抛出异常。
- 减轻finally的任务，不要在finally中做一些其它的事情，finally块仅仅用来释放资源是最合适的。
- 将尽量将所有的return写在函数的最后面，而不是try ... catch ... finally中。
 

## 解答
### 使用 try-catch 为什么比较耗费性能？
答：这个问题要从 JVM（Java 虚拟机）层面找答案了。首先 Java 虚拟机在构造异常实例的时候需要生成该异常的栈轨迹，这个操作会逐一访问当前线程的栈帧，并且记录下各种调试信息，包括栈帧所指向方法的名字，方法所在的类名、文件名，以及在代码中的第几行触发该异常等信息，这就是使用异常捕获耗时的主要原因了。

### 为什么 finally 总能被执行？
答：finally 总会被执行，都是编译器的作用，因为编译器在编译 Java 代码时，会复制 finally 代码块的内容，然后分别放在 try-catch 代码块所有的正常执行路径及异常执行路径的出口中，这样 finally 才会不管发生什么情况都会执行。

### NoClassDefFoundError 和ClassNotFoundException 有什么区别：


1. NoClassDefFoundError 是 Error（错误）类型，而 ClassNoFoundExcept 是 Exception（异常）类型；
1. ClassNoFoundExcept 是 Java 使用 Class.forName 方法动态加载类，没有加载到，就会抛出 ClassNoFoundExcept 异常；
1. NoClassDefFoundError 是 Java 虚拟机或者 ClassLoader 尝试加载类的时候却找不到类订阅导致的，也就是说要查找的类在编译的时候是存在的，运行的时候却找不到，这个时候就会出现 NoClassDefFoundError 的错误。

### finally 里也发生了异常，程序会怎么运行？

```
try {
    System.out.println("try");
} catch (Exception e) {
    System.out.println("catch");
} finally {
    int k = 3 / 0;
    System.out.println("finally");
}
System.out.println("main");
```

答：程序在输出 try 之后抛出异常并终止运行，不会再执行 finally 异常之后的代码。

### catch 里也发生了异常，程序会怎么执行？

```
try {
    int i = 10 / 0;
    System.out.println("try");
} catch (Exception e) {
    int j = 2 / 0;
    System.out.println("catch");
} finally {
    System.out.println("finally");
}
System.out.println("main");
```

答：程序会打印出 finally 之后抛出异常并终止运行。